Traceback (most recent call last):
  File "C:\Users\Jon\AppData\Local\Packages\PythonSoftwareFoundation.Python.3.11_qbz5n2kfra8p0\LocalCache\local-packages\Python311\site-packages\jupyter_cache\executors\utils.py", line 58, in single_nb_execution
    executenb(
  File "C:\Users\Jon\AppData\Local\Packages\PythonSoftwareFoundation.Python.3.11_qbz5n2kfra8p0\LocalCache\local-packages\Python311\site-packages\nbclient\client.py", line 1305, in execute
    return NotebookClient(nb=nb, resources=resources, km=km, **kwargs).execute()
           ^^^^^^^^^^^^^^^^^^^^^^^^^^^^^^^^^^^^^^^^^^^^^^^^^^^^^^^^^^^^^^^^^^^^^
  File "C:\Users\Jon\AppData\Local\Packages\PythonSoftwareFoundation.Python.3.11_qbz5n2kfra8p0\LocalCache\local-packages\Python311\site-packages\jupyter_core\utils\__init__.py", line 166, in wrapped
    return loop.run_until_complete(inner)
           ^^^^^^^^^^^^^^^^^^^^^^^^^^^^^^
  File "C:\Program Files\WindowsApps\PythonSoftwareFoundation.Python.3.11_3.11.1776.0_x64__qbz5n2kfra8p0\Lib\asyncio\base_events.py", line 653, in run_until_complete
    return future.result()
           ^^^^^^^^^^^^^^^
  File "C:\Users\Jon\AppData\Local\Packages\PythonSoftwareFoundation.Python.3.11_qbz5n2kfra8p0\LocalCache\local-packages\Python311\site-packages\nbclient\client.py", line 705, in async_execute
    await self.async_execute_cell(
  File "C:\Users\Jon\AppData\Local\Packages\PythonSoftwareFoundation.Python.3.11_qbz5n2kfra8p0\LocalCache\local-packages\Python311\site-packages\nbclient\client.py", line 1058, in async_execute_cell
    await self._check_raise_for_error(cell, cell_index, exec_reply)
  File "C:\Users\Jon\AppData\Local\Packages\PythonSoftwareFoundation.Python.3.11_qbz5n2kfra8p0\LocalCache\local-packages\Python311\site-packages\nbclient\client.py", line 914, in _check_raise_for_error
    raise CellExecutionError.from_cell_and_msg(cell, exec_reply_content)
nbclient.exceptions.CellExecutionError: An error occurred while executing the following cell:
------------------
import numpy as np
import matplotlib.pyplot as plt
from myst_nb import glue
plt.rcParams['text.usetex'] = True

t = np.linspace(0, 1, 200)
fig, ax = plt.subplots()
for i in range(1, 12):
    if i == 4:
        continue
    plt.plot(t, np.exp(t + np.log(i*0.25)), "b")
plt.plot(t, np.exp(t), "r")
plt.plot(t, np.exp(t + np.log(2)), "g")
plt.plot(0, 1, "ro")
plt.plot(0, 2, "go")
plt.annotate("$y(0)=1$", xy=(-0.01, 1), xytext=(-0.25, 1.3), fontsize=14, color="r",
             arrowprops=dict(arrowstyle='->',shrinkA=2, shrinkB=2, ec="r"))
plt.annotate("$y = e^{t + \ln(1)}$", xy=(1.01, np.exp(1)), xytext=(1.1, np.exp(1)), fontsize=14, color="r",
            arrowprops=dict(arrowstyle="->", shrinkA=2, shrinkB=2, ec="r"))
plt.annotate("$y(0)=2$", xy=(-0.01, 2), xytext=(-0.25, 2.3), fontsize=14, color="g",
             arrowprops=dict(arrowstyle='->',shrinkA=2, shrinkB=2, ec="g"))
plt.annotate("$y = e^{t+\ln(2)}$", xy=(1.01, np.exp(1 + np.log(2))), xytext=(1.1, np.exp(1 + np.log(2))), fontsize=14, color="g",
            arrowprops=dict(arrowstyle="->", shrinkA=2, shrinkB=2, ec="g"))
plt.xlabel("$t$", fontsize=14)
plt.ylabel("$y$", fontsize=14)
plt.show()

glue("ode_plot", fig, display=False)
------------------


[1;31m----------------------------------------------------------------------[0m
[1;31mModuleNotFoundError[0m                  Traceback (most recent call last)
Cell [1;32mIn[1], line 1[0m
[1;32m----> 1[0m [38;5;28;01mimport[39;00m [38;5;21;01mnumpy[39;00m [38;5;28;01mas[39;00m [38;5;21;01mnp[39;00m
[0;32m      2[0m [38;5;28;01mimport[39;00m [38;5;21;01mmatplotlib[39;00m[38;5;21;01m.[39;00m[38;5;21;01mpyplot[39;00m [38;5;28;01mas[39;00m [38;5;21;01mplt[39;00m
[0;32m      3[0m [38;5;28;01mfrom[39;00m [38;5;21;01mmyst_nb[39;00m [38;5;28;01mimport[39;00m glue

[1;31mModuleNotFoundError[0m: No module named 'numpy'

