Traceback (most recent call last):
  File "C:\Users\Jon\AppData\Local\Packages\PythonSoftwareFoundation.Python.3.11_qbz5n2kfra8p0\LocalCache\local-packages\Python311\site-packages\jupyter_cache\executors\utils.py", line 58, in single_nb_execution
    executenb(
  File "C:\Users\Jon\AppData\Local\Packages\PythonSoftwareFoundation.Python.3.11_qbz5n2kfra8p0\LocalCache\local-packages\Python311\site-packages\nbclient\client.py", line 1305, in execute
    return NotebookClient(nb=nb, resources=resources, km=km, **kwargs).execute()
           ^^^^^^^^^^^^^^^^^^^^^^^^^^^^^^^^^^^^^^^^^^^^^^^^^^^^^^^^^^^^^^^^^^^^^
  File "C:\Users\Jon\AppData\Local\Packages\PythonSoftwareFoundation.Python.3.11_qbz5n2kfra8p0\LocalCache\local-packages\Python311\site-packages\jupyter_core\utils\__init__.py", line 166, in wrapped
    return loop.run_until_complete(inner)
           ^^^^^^^^^^^^^^^^^^^^^^^^^^^^^^
  File "C:\Program Files\WindowsApps\PythonSoftwareFoundation.Python.3.11_3.11.1776.0_x64__qbz5n2kfra8p0\Lib\asyncio\base_events.py", line 653, in run_until_complete
    return future.result()
           ^^^^^^^^^^^^^^^
  File "C:\Users\Jon\AppData\Local\Packages\PythonSoftwareFoundation.Python.3.11_qbz5n2kfra8p0\LocalCache\local-packages\Python311\site-packages\nbclient\client.py", line 705, in async_execute
    await self.async_execute_cell(
  File "C:\Users\Jon\AppData\Local\Packages\PythonSoftwareFoundation.Python.3.11_qbz5n2kfra8p0\LocalCache\local-packages\Python311\site-packages\nbclient\client.py", line 1058, in async_execute_cell
    await self._check_raise_for_error(cell, cell_index, exec_reply)
  File "C:\Users\Jon\AppData\Local\Packages\PythonSoftwareFoundation.Python.3.11_qbz5n2kfra8p0\LocalCache\local-packages\Python311\site-packages\nbclient\client.py", line 914, in _check_raise_for_error
    raise CellExecutionError.from_cell_and_msg(cell, exec_reply_content)
nbclient.exceptions.CellExecutionError: An error occurred while executing the following cell:
------------------
import numpy as np
import matplotlib.pyplot as plt
plt.rcParams['text.usetex'] = True  # use LaTeX commands in plot

# Euler method function
def euler(f, t, y, h): 
    return y + h * f(t, y)


# IVP solver function
def solveIVP(f, tspan, y0, h, solver):

    # Initialise t and y arrays
    t = np.arange(tspan[0], tspan[1] + h, h)
    y = np.zeros((len(t),len(y0)))
    t[0] = tspan[0]
    y[0,:] = y0

    # Loop through steps and calculate single step solver solution
    for n in range(len(t) - 1):
        y[n+1,:] = solver(f, t[n], y[n,:], h)
              
    return t, y


# Define ODE function (van der Pol equation)
def f(t,y):
    return np.array([ y[1], mu* (1 - y[0] ** 2) * y[1] - y[0] ])

# Define IVP parameters
tspan = [0, 20]  # boundaries of the t domain
y0 = [2, 0]      # initial values
h = 0.1          # step length
mu = 1           # dampening parameter

# Solve the IVP using the Euler method
t, y = solveIVP(f, tspan, y0, h, euler)

# Plot solution
fig, ax = plt.subplots()
plt.plot(t, y[:,0], "b-")
plt.xlabel("$t$", fontsize=12)
plt.ylabel("$y$", fontsize=12)
plt.show()

print(y)

from myst_nb import glue
glue("system_odes_plot", fig, display=False)
------------------


[1;31m----------------------------------------------------------------------[0m
[1;31mModuleNotFoundError[0m                  Traceback (most recent call last)
Cell [1;32mIn[1], line 1[0m
[1;32m----> 1[0m [38;5;28;01mimport[39;00m [38;5;21;01mnumpy[39;00m [38;5;28;01mas[39;00m [38;5;21;01mnp[39;00m
[0;32m      2[0m [38;5;28;01mimport[39;00m [38;5;21;01mmatplotlib[39;00m[38;5;21;01m.[39;00m[38;5;21;01mpyplot[39;00m [38;5;28;01mas[39;00m [38;5;21;01mplt[39;00m
[0;32m      3[0m plt[38;5;241m.[39mrcParams[[38;5;124m'[39m[38;5;124mtext.usetex[39m[38;5;124m'[39m] [38;5;241m=[39m [38;5;28;01mTrue[39;00m  [38;5;66;03m# use LaTeX commands in plot[39;00m

[1;31mModuleNotFoundError[0m: No module named 'numpy'

