Traceback (most recent call last):
  File "C:\Users\Jon\AppData\Local\Packages\PythonSoftwareFoundation.Python.3.11_qbz5n2kfra8p0\LocalCache\local-packages\Python311\site-packages\jupyter_cache\executors\utils.py", line 58, in single_nb_execution
    executenb(
  File "C:\Users\Jon\AppData\Local\Packages\PythonSoftwareFoundation.Python.3.11_qbz5n2kfra8p0\LocalCache\local-packages\Python311\site-packages\nbclient\client.py", line 1305, in execute
    return NotebookClient(nb=nb, resources=resources, km=km, **kwargs).execute()
           ^^^^^^^^^^^^^^^^^^^^^^^^^^^^^^^^^^^^^^^^^^^^^^^^^^^^^^^^^^^^^^^^^^^^^
  File "C:\Users\Jon\AppData\Local\Packages\PythonSoftwareFoundation.Python.3.11_qbz5n2kfra8p0\LocalCache\local-packages\Python311\site-packages\jupyter_core\utils\__init__.py", line 166, in wrapped
    return loop.run_until_complete(inner)
           ^^^^^^^^^^^^^^^^^^^^^^^^^^^^^^
  File "C:\Program Files\WindowsApps\PythonSoftwareFoundation.Python.3.11_3.11.1776.0_x64__qbz5n2kfra8p0\Lib\asyncio\base_events.py", line 653, in run_until_complete
    return future.result()
           ^^^^^^^^^^^^^^^
  File "C:\Users\Jon\AppData\Local\Packages\PythonSoftwareFoundation.Python.3.11_qbz5n2kfra8p0\LocalCache\local-packages\Python311\site-packages\nbclient\client.py", line 705, in async_execute
    await self.async_execute_cell(
  File "C:\Users\Jon\AppData\Local\Packages\PythonSoftwareFoundation.Python.3.11_qbz5n2kfra8p0\LocalCache\local-packages\Python311\site-packages\nbclient\client.py", line 1058, in async_execute_cell
    await self._check_raise_for_error(cell, cell_index, exec_reply)
  File "C:\Users\Jon\AppData\Local\Packages\PythonSoftwareFoundation.Python.3.11_qbz5n2kfra8p0\LocalCache\local-packages\Python311\site-packages\nbclient\client.py", line 914, in _check_raise_for_error
    raise CellExecutionError.from_cell_and_msg(cell, exec_reply_content)
nbclient.exceptions.CellExecutionError: An error occurred while executing the following cell:
------------------
import sympy as sp

# Declare symbolic variables
a21, a31, a32, a41, a42, a43, b1, b2, b3, b4, c2, c3, c4 \
    = sp.symbols("a21, a31, a32, a41, a42, a43, b1, b2, b3, b4, c2, c3, c4")
c2, c3, c4 = sp.Rational(1,2), sp.Rational(1,2), 1

# Define order conditions
eq1 = b1 + b2 + b3 + b4 - 1
eq2 = b2 * c2 + b3 * c3 + b4 * c4 - sp.Rational(1,2)
eq3 = b2 * c2 ** 2 + b3 * c3 ** 2 + b4 * c4 ** 2 - sp.Rational(1,3)
eq4 = b2 * c2 ** 3 + b3 * c3 ** 3 + b4 * c4 ** 3 - sp.Rational(1,4)
eq5 = b2 * a32 * c2 + b4 * a42 * c2 + b4 * a43 * c3 - sp.Rational(1,6)
eq6 = b3 * a32 * c2 * c3 + b4 * a42 * c2 * c4 + b4 * a43 * c3 * c4 - sp.Rational(1,8)
eq7 = b3 * a32 * c2 ** 2 + b4 * a42 * c2 ** 2 + b4 * a43 * c3 ** 2 - sp.Rational(1,12)
eq8 = b4 * a43 * a32 * c2 - sp.Rational(1,24)
eq9 = a21 - c2
eq10 = a31 + a32 - c3
eq11 = a41 + a42 + a43 - c4

# Solve order conditions
sp.solve((eq1, eq2, eq3, eq4, eq5, eq6, eq7, eq8, eq9, eq10, eq11), dict=True)
------------------


[1;31m---------------------------------------------------------------------------[0m
[1;31mModuleNotFoundError[0m                       Traceback (most recent call last)
Cell [1;32mIn[1], line 1[0m
[1;32m----> 1[0m [38;5;28;01mimport[39;00m [38;5;21;01msympy[39;00m [38;5;28;01mas[39;00m [38;5;21;01msp[39;00m
[0;32m      3[0m [38;5;66;03m# Declare symbolic variables[39;00m
[0;32m      4[0m a21, a31, a32, a41, a42, a43, b1, b2, b3, b4, c2, c3, c4 \
[0;32m      5[0m     [38;5;241m=[39m sp[38;5;241m.[39msymbols([38;5;124m"[39m[38;5;124ma21, a31, a32, a41, a42, a43, b1, b2, b3, b4, c2, c3, c4[39m[38;5;124m"[39m)

[1;31mModuleNotFoundError[0m: No module named 'sympy'

