Traceback (most recent call last):
  File "C:\Users\jonsh\AppData\Local\Packages\PythonSoftwareFoundation.Python.3.9_qbz5n2kfra8p0\LocalCache\local-packages\Python39\site-packages\jupyter_cache\executors\utils.py", line 51, in single_nb_execution
    executenb(
  File "C:\Users\jonsh\AppData\Local\Packages\PythonSoftwareFoundation.Python.3.9_qbz5n2kfra8p0\LocalCache\local-packages\Python39\site-packages\nbclient\client.py", line 1204, in execute
    return NotebookClient(nb=nb, resources=resources, km=km, **kwargs).execute()
  File "C:\Users\jonsh\AppData\Local\Packages\PythonSoftwareFoundation.Python.3.9_qbz5n2kfra8p0\LocalCache\local-packages\Python39\site-packages\nbclient\util.py", line 84, in wrapped
    return just_run(coro(*args, **kwargs))
  File "C:\Users\jonsh\AppData\Local\Packages\PythonSoftwareFoundation.Python.3.9_qbz5n2kfra8p0\LocalCache\local-packages\Python39\site-packages\nbclient\util.py", line 62, in just_run
    return loop.run_until_complete(coro)
  File "C:\Program Files\WindowsApps\PythonSoftwareFoundation.Python.3.9_3.9.3568.0_x64__qbz5n2kfra8p0\lib\asyncio\base_events.py", line 647, in run_until_complete
    return future.result()
  File "C:\Users\jonsh\AppData\Local\Packages\PythonSoftwareFoundation.Python.3.9_qbz5n2kfra8p0\LocalCache\local-packages\Python39\site-packages\nbclient\client.py", line 663, in async_execute
    await self.async_execute_cell(
  File "C:\Users\jonsh\AppData\Local\Packages\PythonSoftwareFoundation.Python.3.9_qbz5n2kfra8p0\LocalCache\local-packages\Python39\site-packages\nbclient\client.py", line 965, in async_execute_cell
    await self._check_raise_for_error(cell, cell_index, exec_reply)
  File "C:\Users\jonsh\AppData\Local\Packages\PythonSoftwareFoundation.Python.3.9_qbz5n2kfra8p0\LocalCache\local-packages\Python39\site-packages\nbclient\client.py", line 862, in _check_raise_for_error
    raise CellExecutionError.from_cell_and_msg(cell, exec_reply_content)
nbclient.exceptions.CellExecutionError: An error occurred while executing the following cell:
------------------
import numpy as np
import matplotlib.pyplot as plt


def f(t, y):
    return t * y

# Define IVP
tspan = [0, 1]  # boundaries of the t domain
y0 = [1]        # solution at the lower boundary
h = 0.2         # step length

nsteps = int((tspan[1] - tspan[0]) / h)
neq = len(y0)
t = np.arange(nsteps + 1) * h
y = np.zeros((nsteps + 1, neq))
y[0,:] = y0

print(r"\begin{align*}")
for n in range(nsteps):
    k1 = f(t[n], y[n,:])
    k2 = f(t[n] + h, y[n,:] + h * k1)
    y[n+1,:] = y[n,:] + h / 2 * (k1 + k2)
    print(rf"    k_1 &= f(t_{n}, y_{n}) = ({t[n]:0.1f})({y[n,0]:0.6f}) = {k1[0]:0.6f}, \\")
    print(rf"    k_2 &= f(t_{n} + h, y_{n} + hk_1) = ({t[n]:0.1f} + {h})({y[n,0]:0.6f} + {h}({k1[0]:0.6f})) \\")
    print(rf"    &= {k2[0]:0.6f}, \\")
    print(rf"    y_{n+1} &= y_{n} + \frac{{h}}{{2}}(k_1 + k_2) = {y[n,0]:0.6f} + {h/2}({k1[0]:0.6f} + {k2[0]:0.6f}) \\")
    print(rf"    &= {y[n,0]:0.6f}", end="")
    if n < nsteps - 1:
        print(rf", \\ \\")
    else:
        print(rf".")

print(r"\end{align*}")
------------------

[1;31m---------------------------------------------------------------------------[0m
[1;31mModuleNotFoundError[0m                       Traceback (most recent call last)
Cell [1;32mIn [1], line 1[0m
[1;32m----> 1[0m [38;5;28;01mimport[39;00m [38;5;21;01mnumpy[39;00m [38;5;28;01mas[39;00m [38;5;21;01mnp[39;00m
[0;32m      2[0m [38;5;28;01mimport[39;00m [38;5;21;01mmatplotlib[39;00m[38;5;21;01m.[39;00m[38;5;21;01mpyplot[39;00m [38;5;28;01mas[39;00m [38;5;21;01mplt[39;00m
[0;32m      5[0m [38;5;28;01mdef[39;00m [38;5;21mf[39m(t, y):

[1;31mModuleNotFoundError[0m: No module named 'numpy'
ModuleNotFoundError: No module named 'numpy'

