Traceback (most recent call last):
  File "/Volumes/DataHD/jon/opt/anaconda3/lib/python3.8/site-packages/jupyter_cache/executors/utils.py", line 51, in single_nb_execution
    executenb(
  File "/Volumes/DataHD/jon/opt/anaconda3/lib/python3.8/site-packages/nbclient/client.py", line 1204, in execute
    return NotebookClient(nb=nb, resources=resources, km=km, **kwargs).execute()
  File "/Volumes/DataHD/jon/opt/anaconda3/lib/python3.8/site-packages/nbclient/util.py", line 84, in wrapped
    return just_run(coro(*args, **kwargs))
  File "/Volumes/DataHD/jon/opt/anaconda3/lib/python3.8/site-packages/nbclient/util.py", line 62, in just_run
    return loop.run_until_complete(coro)
  File "/Volumes/DataHD/jon/opt/anaconda3/lib/python3.8/asyncio/base_events.py", line 616, in run_until_complete
    return future.result()
  File "/Volumes/DataHD/jon/opt/anaconda3/lib/python3.8/site-packages/nbclient/client.py", line 663, in async_execute
    await self.async_execute_cell(
  File "/Volumes/DataHD/jon/opt/anaconda3/lib/python3.8/site-packages/nbclient/client.py", line 965, in async_execute_cell
    await self._check_raise_for_error(cell, cell_index, exec_reply)
  File "/Volumes/DataHD/jon/opt/anaconda3/lib/python3.8/site-packages/nbclient/client.py", line 862, in _check_raise_for_error
    raise CellExecutionError.from_cell_and_msg(cell, exec_reply_content)
nbclient.exceptions.CellExecutionError: An error occurred while executing the following cell:
------------------
# Calculate solution for decreasing step lengths and plot the solution
h = [0.4, 0.2, 0.1, 0.05]
e = np.zeros((len(h), 2))
for i in range(len(h)):
    t, y = myrk2(f, tspan, y0, h[i])
    e[i,0] = abs(y_exact[-1] - y[-1,0])
    t, y = myrk4(f, tspan, y0, h[i])
    e[i,1] = abs(y_exact[-1] - y[-1,0])

# Plot errors
fig, ax = plt.subplots(figsize=(8, 6))
plt.loglog(h, e[:,0], "bo-", label="myRK2")
plt.loglog(h, e[:,1], "ro-", label="myRK4")
plt.xlabel(r"$\log(h)$", fontsize=16)
plt.ylabel(r"$\log(e_n)$", fontsize=16)
plt.legend(fontsize=12)
plt.show()

# Output table of errors
print("|   h   | myRK2 error | myRK4 error |")
print("|:-----:|:-----------:|:-----------:|")
for i in range(len(h_vals)):
    print(f"| {h[i]:5.3f} |   {e[i,0]:0.2e}  |   {e[i,1]:0.2e}  |")
print()
    
# Estimate the order of the methods
order = (np.log(e[0,:]) - np.log(e[-1,:])) / (np.log(h[0]) - np.log(h[-1]))
print(f"myRK2 order = {order[0]:0.2f}\nmyRK4 order = {order[1]:0.2f}")

------------------

[0;31m---------------------------------------------------------------------------[0m
[0;31mNameError[0m                                 Traceback (most recent call last)
[0;32m<ipython-input-9-852f44991c27>[0m in [0;36m<module>[0;34m[0m
[1;32m     20[0m [0mprint[0m[0;34m([0m[0;34m"|   h   | myRK2 error | myRK4 error |"[0m[0;34m)[0m[0;34m[0m[0;34m[0m[0m
[1;32m     21[0m [0mprint[0m[0;34m([0m[0;34m"|:-----:|:-----------:|:-----------:|"[0m[0;34m)[0m[0;34m[0m[0;34m[0m[0m
[0;32m---> 22[0;31m [0;32mfor[0m [0mi[0m [0;32min[0m [0mrange[0m[0;34m([0m[0mlen[0m[0;34m([0m[0mh_vals[0m[0;34m)[0m[0;34m)[0m[0;34m:[0m[0;34m[0m[0;34m[0m[0m
[0m[1;32m     23[0m     [0mprint[0m[0;34m([0m[0;34mf"| {h[i]:5.3f} |   {e[i,0]:0.2e}  |   {e[i,1]:0.2e}  |"[0m[0;34m)[0m[0;34m[0m[0;34m[0m[0m
[1;32m     24[0m [0mprint[0m[0;34m([0m[0;34m)[0m[0;34m[0m[0;34m[0m[0m

[0;31mNameError[0m: name 'h_vals' is not defined
NameError: name 'h_vals' is not defined

