Traceback (most recent call last):
  File "C:\Users\jonsh\AppData\Local\Packages\PythonSoftwareFoundation.Python.3.9_qbz5n2kfra8p0\LocalCache\local-packages\Python39\site-packages\nbclient\client.py", line 730, in _async_poll_for_reply
    msg = await ensure_async(self.kc.shell_channel.get_msg(timeout=new_timeout))
  File "C:\Users\jonsh\AppData\Local\Packages\PythonSoftwareFoundation.Python.3.9_qbz5n2kfra8p0\LocalCache\local-packages\Python39\site-packages\nbclient\util.py", line 96, in ensure_async
    result = await obj
  File "C:\Users\jonsh\AppData\Local\Packages\PythonSoftwareFoundation.Python.3.9_qbz5n2kfra8p0\LocalCache\local-packages\Python39\site-packages\jupyter_client\channels.py", line 230, in get_msg
    raise Empty
_queue.Empty

During handling of the above exception, another exception occurred:

Traceback (most recent call last):
  File "C:\Users\jonsh\AppData\Local\Packages\PythonSoftwareFoundation.Python.3.9_qbz5n2kfra8p0\LocalCache\local-packages\Python39\site-packages\jupyter_cache\executors\utils.py", line 51, in single_nb_execution
    executenb(
  File "C:\Users\jonsh\AppData\Local\Packages\PythonSoftwareFoundation.Python.3.9_qbz5n2kfra8p0\LocalCache\local-packages\Python39\site-packages\nbclient\client.py", line 1204, in execute
    return NotebookClient(nb=nb, resources=resources, km=km, **kwargs).execute()
  File "C:\Users\jonsh\AppData\Local\Packages\PythonSoftwareFoundation.Python.3.9_qbz5n2kfra8p0\LocalCache\local-packages\Python39\site-packages\nbclient\util.py", line 84, in wrapped
    return just_run(coro(*args, **kwargs))
  File "C:\Users\jonsh\AppData\Local\Packages\PythonSoftwareFoundation.Python.3.9_qbz5n2kfra8p0\LocalCache\local-packages\Python39\site-packages\nbclient\util.py", line 62, in just_run
    return loop.run_until_complete(coro)
  File "C:\Program Files\WindowsApps\PythonSoftwareFoundation.Python.3.9_3.9.3568.0_x64__qbz5n2kfra8p0\lib\asyncio\base_events.py", line 647, in run_until_complete
    return future.result()
  File "C:\Users\jonsh\AppData\Local\Packages\PythonSoftwareFoundation.Python.3.9_qbz5n2kfra8p0\LocalCache\local-packages\Python39\site-packages\nbclient\client.py", line 663, in async_execute
    await self.async_execute_cell(
  File "C:\Users\jonsh\AppData\Local\Packages\PythonSoftwareFoundation.Python.3.9_qbz5n2kfra8p0\LocalCache\local-packages\Python39\site-packages\nbclient\client.py", line 949, in async_execute_cell
    exec_reply = await self.task_poll_for_reply
  File "C:\Users\jonsh\AppData\Local\Packages\PythonSoftwareFoundation.Python.3.9_qbz5n2kfra8p0\LocalCache\local-packages\Python39\site-packages\nbclient\client.py", line 754, in _async_poll_for_reply
    await self._async_handle_timeout(timeout, cell)
  File "C:\Users\jonsh\AppData\Local\Packages\PythonSoftwareFoundation.Python.3.9_qbz5n2kfra8p0\LocalCache\local-packages\Python39\site-packages\nbclient\client.py", line 801, in _async_handle_timeout
    raise CellTimeoutError.error_from_timeout_and_cell(
nbclient.exceptions.CellTimeoutError: A cell timed out while it was being executed, after 30 seconds.
The message was: Cell execution timed out.
Here is a preview of the cell contents:
-------------------
['from sympy import *', 'from myst_nb import glue', 'init_printing()', '', '# Define Legendre polynomial']
...
['# Solve order conditions', 'solve((eq1, eq2, eq3, eq4, eq5, eq6))', '', 'glue("ex3.3_output_1", solve(P(2) - P(1)), display=False)', 'glue("ex3.3_output_2", solve((eq1, eq2, eq3, eq4, eq5, eq6)))']
-------------------

