Traceback (most recent call last):
  File "C:\Users\jonsh\AppData\Local\Packages\PythonSoftwareFoundation.Python.3.9_qbz5n2kfra8p0\LocalCache\local-packages\Python39\site-packages\jupyter_cache\executors\utils.py", line 51, in single_nb_execution
    executenb(
  File "C:\Users\jonsh\AppData\Local\Packages\PythonSoftwareFoundation.Python.3.9_qbz5n2kfra8p0\LocalCache\local-packages\Python39\site-packages\nbclient\client.py", line 1204, in execute
    return NotebookClient(nb=nb, resources=resources, km=km, **kwargs).execute()
  File "C:\Users\jonsh\AppData\Local\Packages\PythonSoftwareFoundation.Python.3.9_qbz5n2kfra8p0\LocalCache\local-packages\Python39\site-packages\nbclient\util.py", line 84, in wrapped
    return just_run(coro(*args, **kwargs))
  File "C:\Users\jonsh\AppData\Local\Packages\PythonSoftwareFoundation.Python.3.9_qbz5n2kfra8p0\LocalCache\local-packages\Python39\site-packages\nbclient\util.py", line 62, in just_run
    return loop.run_until_complete(coro)
  File "C:\Program Files\WindowsApps\PythonSoftwareFoundation.Python.3.9_3.9.3568.0_x64__qbz5n2kfra8p0\lib\asyncio\base_events.py", line 647, in run_until_complete
    return future.result()
  File "C:\Users\jonsh\AppData\Local\Packages\PythonSoftwareFoundation.Python.3.9_qbz5n2kfra8p0\LocalCache\local-packages\Python39\site-packages\nbclient\client.py", line 663, in async_execute
    await self.async_execute_cell(
  File "C:\Users\jonsh\AppData\Local\Packages\PythonSoftwareFoundation.Python.3.9_qbz5n2kfra8p0\LocalCache\local-packages\Python39\site-packages\nbclient\client.py", line 965, in async_execute_cell
    await self._check_raise_for_error(cell, cell_index, exec_reply)
  File "C:\Users\jonsh\AppData\Local\Packages\PythonSoftwareFoundation.Python.3.9_qbz5n2kfra8p0\LocalCache\local-packages\Python39\site-packages\nbclient\client.py", line 862, in _check_raise_for_error
    raise CellExecutionError.from_cell_and_msg(cell, exec_reply_content)
nbclient.exceptions.CellExecutionError: An error occurred while executing the following cell:
------------------
import numpy as np
import matplotlib.pyplot as plt

def euler(f, tspan, y0, h):
    nsteps = int((tspan[1] - tspan[0]) / h)
    neq = len(y0)
    t = np.arange(nsteps + 1) * h
    y = np.zeros((nsteps + 1, neq))
    y[0,:] = y0
    for n in range(nsteps):
        y[n+1,:] = y[n,:] + h * f(t[n], y[n,:])
        
    return t, y 


def f(t, y):
    return np.array([y[1], 2 * t])

# Define BVP parameters
tspan = [0, 2]  # boundaries of the t domain
bvals = [1, 3]  # boundary values
h = 0.4         # step length
svals = [1, -1]

# Solve IVP
ysols = []
for s in svals:
    t, y = euler(f, tspan, [bvals[0], s], h)
    ysols.append(y)
    
    print("\n|  t   |   y1    |   y2    |")
    print("|:----:|:-------:|:-------:|")
    for n in range(len(t)):
        print(f"| {t[n]:4.2f} | {y[n,0]:7.4f} | {y[n,1]:7.4f} |")
        
# Calculate next guess
s = svals[-1] - (bvals[1] - ysols[-1][-1,0]) * (svals[-1] - svals[-2]) / ((bvals[1] - ysols[-1][-1,0]) - (bvals[1] - ysols[-2][-1,0]))

# Solve IVP
t, y = euler(f, tspan, [bvals[0], s], h)

print("\n|  t   |   y1    |   y2    |")
print("|:----:|:-------:|:-------:|")
for n in range(len(t)):
    print(f"| {t[n]:4.2f} | {y[n,0]:7.4f} | {y[n,1]:7.4f} |")
------------------

[1;31m---------------------------------------------------------------------------[0m
[1;31mModuleNotFoundError[0m                       Traceback (most recent call last)
Cell [1;32mIn [1], line 1[0m
[1;32m----> 1[0m [38;5;28;01mimport[39;00m [38;5;21;01mnumpy[39;00m [38;5;28;01mas[39;00m [38;5;21;01mnp[39;00m
[0;32m      2[0m [38;5;28;01mimport[39;00m [38;5;21;01mmatplotlib[39;00m[38;5;21;01m.[39;00m[38;5;21;01mpyplot[39;00m [38;5;28;01mas[39;00m [38;5;21;01mplt[39;00m
[0;32m      4[0m [38;5;28;01mdef[39;00m [38;5;21meuler[39m(f, tspan, y0, h):

[1;31mModuleNotFoundError[0m: No module named 'numpy'
ModuleNotFoundError: No module named 'numpy'

