Traceback (most recent call last):
  File "C:\Users\jonsh\AppData\Local\Packages\PythonSoftwareFoundation.Python.3.9_qbz5n2kfra8p0\LocalCache\local-packages\Python39\site-packages\jupyter_cache\executors\utils.py", line 51, in single_nb_execution
    executenb(
  File "C:\Users\jonsh\AppData\Local\Packages\PythonSoftwareFoundation.Python.3.9_qbz5n2kfra8p0\LocalCache\local-packages\Python39\site-packages\nbclient\client.py", line 1204, in execute
    return NotebookClient(nb=nb, resources=resources, km=km, **kwargs).execute()
  File "C:\Users\jonsh\AppData\Local\Packages\PythonSoftwareFoundation.Python.3.9_qbz5n2kfra8p0\LocalCache\local-packages\Python39\site-packages\nbclient\util.py", line 84, in wrapped
    return just_run(coro(*args, **kwargs))
  File "C:\Users\jonsh\AppData\Local\Packages\PythonSoftwareFoundation.Python.3.9_qbz5n2kfra8p0\LocalCache\local-packages\Python39\site-packages\nbclient\util.py", line 62, in just_run
    return loop.run_until_complete(coro)
  File "C:\Program Files\WindowsApps\PythonSoftwareFoundation.Python.3.9_3.9.3568.0_x64__qbz5n2kfra8p0\lib\asyncio\base_events.py", line 647, in run_until_complete
    return future.result()
  File "C:\Users\jonsh\AppData\Local\Packages\PythonSoftwareFoundation.Python.3.9_qbz5n2kfra8p0\LocalCache\local-packages\Python39\site-packages\nbclient\client.py", line 663, in async_execute
    await self.async_execute_cell(
  File "C:\Users\jonsh\AppData\Local\Packages\PythonSoftwareFoundation.Python.3.9_qbz5n2kfra8p0\LocalCache\local-packages\Python39\site-packages\nbclient\client.py", line 965, in async_execute_cell
    await self._check_raise_for_error(cell, cell_index, exec_reply)
  File "C:\Users\jonsh\AppData\Local\Packages\PythonSoftwareFoundation.Python.3.9_qbz5n2kfra8p0\LocalCache\local-packages\Python39\site-packages\nbclient\client.py", line 862, in _check_raise_for_error
    raise CellExecutionError.from_cell_and_msg(cell, exec_reply_content)
nbclient.exceptions.CellExecutionError: An error occurred while executing the following cell:
------------------
import numpy as np
import matplotlib.pyplot as plt
from myst_nb import glue

def euler(f, tspan, y0, h):
    nsteps = int((tspan[1] - tspan[0]) / h)
    neq = len(y0)
    t = np.arange(nsteps + 1) * h
    y = np.zeros((nsteps + 1, neq))
    y[0,:] = y0
    for n in range(nsteps):
        y[n+1,:] = y[n,:] + h * f(t[n], y[n,:])
        
    return t, y 


def rk2(f, tspan, y0, h):
    nsteps = int((tspan[1] - tspan[0]) / h)
    neq = len(y0)
    t = np.arange(nsteps + 1) * h
    y = np.zeros((nsteps + 1, neq))
    y[0,:] = y0
    for n in range(nsteps):
        k1 = f(t[n], y[n,:])
        k2 = f(t[n] + h, y[n,:] + h * k1)
        y[n+1,:] = y[n,:] + h / 2 * (k1 + k2)
        
    return t, y


def f(t, y):
    return np.array([y[1], -y[0]])


def exact(t):
    return 2 * np.cos(t)


# Define IVP
tspan = [0, 10]  # boundaries of the t domain
y0 = [2, 0]      # solution at the lower boundary
h = 0.2          # step length

# Calculate the solution to the IVP
t, y = euler(f, tspan, y0, h)
t_rk2, y_rk2 = rk2(f, tspan, y0, h)

# Calculate exact solution
t_exact = np.linspace(tspan[0], tspan[1], 200)
y_exact = exact(t_exact)

# Table
print("| $t_n$ |  $y_1$  |  $y_2$  |  Exact  |  Error   |")
print("|:-----:|:-------:|:-------:|:-------:|:--------:|")   
for n in range(6):
    print(f"| {t[n]:5.2f} | {y[n,0]:9.6f} | {y[n,1]:9.6f} | {exact(t[n]):9.6f} | {abs(exact(t[n]) - y[n,0]):7.2e} |")
print(r"| $\vdots$ | $\vdots$ | $\vdots$ | $\vdots$ | $\vdots$ |")
print(f"| {t[-1]:5.2f} | {y[-1,0]:9.6f} | {y[-1,1]:9.6f} | {exact(t[-1]):9.6f} | {abs(exact(t[-1]) - y[-1,0]):7.2e} |")
              
# Plot solution
fig, ax = plt.subplots(figsize=(8, 6))
plt.plot(t_exact, y_exact, "k", label="Exact")
plt.plot(t, y[:,0], "bo-", label="Euler")
plt.plot(t, y_rk2[:,0], "ro-", label="RK2")
plt.xlabel("$t$", fontsize=14)
plt.ylabel("$y$", fontsize=14)
plt.legend(fontsize=12)
plt.show()

glue("higher_order_ode_fig", fig, display=False)
------------------

[1;31m---------------------------------------------------------------------------[0m
[1;31mModuleNotFoundError[0m                       Traceback (most recent call last)
Cell [1;32mIn [1], line 1[0m
[1;32m----> 1[0m [38;5;28;01mimport[39;00m [38;5;21;01mnumpy[39;00m [38;5;28;01mas[39;00m [38;5;21;01mnp[39;00m
[0;32m      2[0m [38;5;28;01mimport[39;00m [38;5;21;01mmatplotlib[39;00m[38;5;21;01m.[39;00m[38;5;21;01mpyplot[39;00m [38;5;28;01mas[39;00m [38;5;21;01mplt[39;00m
[0;32m      3[0m [38;5;28;01mfrom[39;00m [38;5;21;01mmyst_nb[39;00m [38;5;28;01mimport[39;00m glue

[1;31mModuleNotFoundError[0m: No module named 'numpy'
ModuleNotFoundError: No module named 'numpy'

