Traceback (most recent call last):
  File "/Volumes/DataHD/jon/opt/anaconda3/lib/python3.8/site-packages/jupyter_cache/executors/utils.py", line 51, in single_nb_execution
    executenb(
  File "/Volumes/DataHD/jon/opt/anaconda3/lib/python3.8/site-packages/nbclient/client.py", line 1204, in execute
    return NotebookClient(nb=nb, resources=resources, km=km, **kwargs).execute()
  File "/Volumes/DataHD/jon/opt/anaconda3/lib/python3.8/site-packages/nbclient/util.py", line 84, in wrapped
    return just_run(coro(*args, **kwargs))
  File "/Volumes/DataHD/jon/opt/anaconda3/lib/python3.8/site-packages/nbclient/util.py", line 62, in just_run
    return loop.run_until_complete(coro)
  File "/Volumes/DataHD/jon/opt/anaconda3/lib/python3.8/asyncio/base_events.py", line 616, in run_until_complete
    return future.result()
  File "/Volumes/DataHD/jon/opt/anaconda3/lib/python3.8/site-packages/nbclient/client.py", line 663, in async_execute
    await self.async_execute_cell(
  File "/Volumes/DataHD/jon/opt/anaconda3/lib/python3.8/site-packages/nbclient/client.py", line 965, in async_execute_cell
    await self._check_raise_for_error(cell, cell_index, exec_reply)
  File "/Volumes/DataHD/jon/opt/anaconda3/lib/python3.8/site-packages/nbclient/client.py", line 862, in _check_raise_for_error
    raise CellExecutionError.from_cell_and_msg(cell, exec_reply_content)
nbclient.exceptions.CellExecutionError: An error occurred while executing the following cell:
------------------
from sympy import *


c = Matrix([3, 2])
P = Matrix([[c[0]-1, c[0]+1, c[0]+1, c[0]-1], [c[1]-1, c[1]-1, c[1]+1, c[1]+1], [1, 1, 1, 1]])
T1 = Matrix([[1, 0, -c[0]], [0, 1, -c[1]], [0, 0, 1]])
theta = pi / 3
R = Matrix([[cos(theta), sin(theta), 0], [-sin(theta), cos(theta), 0], [0, 0, 1]])
T2 = Matrix([[1, 0, c[0]], [0, 1, c[1]], [0, 0, 1]])

P1 = A * P
pprint(P1.evalf(5))
------------------

[0;31m---------------------------------------------------------------------------[0m
[0;31mNameError[0m                                 Traceback (most recent call last)
[0;32m<ipython-input-3-847bb7c8490c>[0m in [0;36m<module>[0;34m[0m
[1;32m      9[0m [0mT2[0m [0;34m=[0m [0mMatrix[0m[0;34m([0m[0;34m[[0m[0;34m[[0m[0;36m1[0m[0;34m,[0m [0;36m0[0m[0;34m,[0m [0mc[0m[0;34m[[0m[0;36m0[0m[0;34m][0m[0;34m][0m[0;34m,[0m [0;34m[[0m[0;36m0[0m[0;34m,[0m [0;36m1[0m[0;34m,[0m [0mc[0m[0;34m[[0m[0;36m1[0m[0;34m][0m[0;34m][0m[0;34m,[0m [0;34m[[0m[0;36m0[0m[0;34m,[0m [0;36m0[0m[0;34m,[0m [0;36m1[0m[0;34m][0m[0;34m][0m[0;34m)[0m[0;34m[0m[0;34m[0m[0m
[1;32m     10[0m [0;34m[0m[0m
[0;32m---> 11[0;31m [0mP1[0m [0;34m=[0m [0mA[0m [0;34m*[0m [0mP[0m[0;34m[0m[0;34m[0m[0m
[0m[1;32m     12[0m [0mpprint[0m[0;34m([0m[0mP1[0m[0;34m.[0m[0mevalf[0m[0;34m([0m[0;36m5[0m[0;34m)[0m[0;34m)[0m[0;34m[0m[0;34m[0m[0m

[0;31mNameError[0m: name 'A' is not defined
NameError: name 'A' is not defined

